TASK [list-cluster-versions : Get machinesets] *********************************
fatal: [bastion-ocp4-int-prod-east]: FAILED! => {"changed": false, "module_stderr": "Shared connection to 10.211.84.244 closed.\r\n", "module_stdout": "Traceback (most recent call last):\r\n  File \"/usr/local/lib/python3.6/site-packages/openshift/dynamic/client.py\", line 42, in inner\r\n    resp = func(self, *args, **kwargs)\r\n  File \"/usr/local/lib/python3.6/site-packages/openshift/dynamic/client.py\", line 247, in request\r\n    _return_http_data_only=params.get('_return_http_data_only', True)\r\n  File \"/usr/local/lib/python3.6/site-packages/kubernetes/client/api_client.py\", line 345, in call_api\r\n    _preload_content, _request_timeout)\r\n  File \"/usr/local/lib/python3.6/site-packages/kubernetes/client/api_client.py\", line 176, in __call_api\r\n    _request_timeout=_request_timeout)\r\n  File \"/usr/local/lib/python3.6/site-packages/kubernetes/client/api_client.py\", line 366, in request\r\n    headers=headers)\r\n  File \"/usr/local/lib/python3.6/site-packages/kubernetes/client/rest.py\", line 241, in GET\r\n    query_params=query_params)\r\n  File \"/usr/local/lib/python3.6/site-packages/kubernetes/client/rest.py\", line 231, in request\r\n    raise ApiException(http_resp=r)\r\nkubernetes.client.rest.ApiException: (403)\r\nReason: Forbidden\r\nHTTP response headers: HTTPHeaderDict({'Audit-Id': '59c13b76-70c6-47b4-95e5-a317f2c6cf7e', 'Cache-Control': 'no-cache, private', 'Content-Type': 'application/json', 'X-Content-Type-Options': 'nosniff', 'X-Kubernetes-Pf-Flowschema-Uid': '62977ac6-7e7d-4511-9e72-5b865d4abcef', 'X-Kubernetes-Pf-Prioritylevel-Uid': '5a65bda9-cd99-4af1-a44a-67666501171d', 'Date': 'Tue, 15 Dec 2020 19:41:18 GMT', 'Content-Length': '392'})\r\nHTTP response body: b'{\"kind\":\"Status\",\"apiVersion\":\"v1\",\"metadata\":{},\"status\":\"Failure\",\"message\":\"machinesets.machine.openshift.io is forbidden: User \\\\\"system:serviceaccount:default:onboarding\\\\\" cannot list resource \\\\\"machinesets\\\\\" in API group \\\\\"machine.openshift.io\\\\\" in the namespace \\\\\"openshift-machine-api\\\\\"\",\"reason\":\"Forbidden\",\"details\":{\"group\":\"machine.openshift.io\",\"kind\":\"machinesets\"},\"code\":403}\\n'\r\n\r\n\r\nDuring handling of the above exception, another exception occurred:\r\n\r\nTraceback (most recent call last):\r\n  File \"/home/ec2-user/.ansible/tmp/ansible-tmp-1608061276.95-6976934200043/AnsiballZ_k8s_facts.py\", line 114, in <module>\r\n    _ansiballz_main()\r\n  File \"/home/ec2-user/.ansible/tmp/ansible-tmp-1608061276.95-6976934200043/AnsiballZ_k8s_facts.py\", line 106, in _ansiballz_main\r\n    invoke_module(zipped_mod, temp_path, ANSIBALLZ_PARAMS)\r\n  File \"/home/ec2-user/.ansible/tmp/ansible-tmp-1608061276.95-6976934200043/AnsiballZ_k8s_facts.py\", line 49, in invoke_module\r\n    imp.load_module('__main__', mod, module, MOD_DESC)\r\n  File \"/usr/lib64/python3.6/imp.py\", line 235, in load_module\r\n    return load_source(name, filename, file)\r\n  File \"/usr/lib64/python3.6/imp.py\", line 170, in load_source\r\n    module = _exec(spec, sys.modules[name])\r\n  File \"<frozen importlib._bootstrap>\", line 618, in _exec\r\n  File \"<frozen importlib._bootstrap_external>\", line 678, in exec_module\r\n  File \"<frozen importlib._bootstrap>\", line 219, in _call_with_frames_removed\r\n  File \"/tmp/ansible_k8s_facts_payload_um1s99h1/__main__.py\", line 176, in <module>\r\n  File \"/tmp/ansible_k8s_facts_payload_um1s99h1/__main__.py\", line 172, in main\r\n  File \"/tmp/ansible_k8s_facts_payload_um1s99h1/__main__.py\", line 153, in execute_module\r\n  File \"/tmp/ansible_k8s_facts_payload_um1s99h1/ansible_k8s_facts_payload.zip/ansible/module_utils/k8s/common.py\", line 206, in kubernetes_facts\r\n  File \"/usr/local/lib/python3.6/site-packages/openshift/dynamic/client.py\", line 94, in get\r\n    return self.request('get', path, **kwargs)\r\n  File \"/usr/local/lib/python3.6/site-packages/openshift/dynamic/client.py\", line 44, in inner\r\n    raise api_exception(e)\r\nopenshift.dynamic.exceptions.ForbiddenError: 403\r\nReason: Forbidden\r\nHTTP response headers: HTTPHeaderDict({'Audit-Id': '59c13b76-70c6-47b4-95e5-a317f2c6cf7e', 'Cache-Control': 'no-cache, private', 'Content-Type': 'application/json', 'X-Content-Type-Options': 'nosniff', 'X-Kubernetes-Pf-Flowschema-Uid': '62977ac6-7e7d-4511-9e72-5b865d4abcef', 'X-Kubernetes-Pf-Prioritylevel-Uid': '5a65bda9-cd99-4af1-a44a-67666501171d', 'Date': 'Tue, 15 Dec 2020 19:41:18 GMT', 'Content-Length': '392'})\r\nHTTP response body: b'{\"kind\":\"Status\",\"apiVersion\":\"v1\",\"metadata\":{},\"status\":\"Failure\",\"message\":\"machinesets.machine.openshift.io is forbidden: User \\\\\"system:serviceaccount:default:onboarding\\\\\" cannot list resource \\\\\"machinesets\\\\\" in API group \\\\\"machine.openshift.io\\\\\" in the namespace \\\\\"openshift-machine-api\\\\\"\",\"reason\":\"Forbidden\",\"details\":{\"group\":\"machine.openshift.io\",\"kind\":\"machinesets\"},\"code\":403}\\n'\r\nOriginal traceback: \r\n  File \"/usr/local/lib/python3.6/site-packages/openshift/dynamic/client.py\", line 42, in inner\r\n    resp = func(self, *args, **kwargs)\r\n\r\n  File \"/usr/local/lib/python3.6/site-packages/openshift/dynamic/client.py\", line 247, in request\r\n    _return_http_data_only=params.get('_return_http_data_only', True)\r\n\r\n  File \"/usr/local/lib/python3.6/site-packages/kubernetes/client/api_client.py\", line 345, in call_api\r\n    _preload_content, _request_timeout)\r\n\r\n  File \"/usr/local/lib/python3.6/site-packages/kubernetes/client/api_client.py\", line 176, in __call_api\r\n    _request_timeout=_request_timeout)\r\n\r\n  File \"/usr/local/lib/python3.6/site-packages/kubernetes/client/api_client.py\", line 366, in request\r\n    headers=headers)\r\n\r\n  File \"/usr/local/lib/python3.6/site-packages/kubernetes/client/rest.py\", line 241, in GET\r\n    query_params=query_params)\r\n\r\n  File \"/usr/local/lib/python3.6/site-packages/kubernetes/client/rest.py\", line 231, in request\r\n    raise ApiException(http_resp=r)\r\n\r\n", "msg": "MODULE FAILURE\nSee stdout/stderr for the exact error", "rc": 1}
fatal: [bastion-ocp4-ext-qa-east]: FAILED! => {"changed": false, "module_stderr": "Shared connection to 10.211.208.203 closed.\r\n", "module_stdout": "Traceback (most recent call last):\r\n  File \"/usr/local/lib/python3.6/site-packages/openshift/dynamic/client.py\", line 42, in inner\r\n    resp = func(self, *args, **kwargs)\r\n  File \"/usr/local/lib/python3.6/site-packages/openshift/dynamic/client.py\", line 247, in request\r\n    _return_http_data_only=params.get('_return_http_data_only', True)\r\n  File \"/usr/local/lib/python3.6/site-packages/kubernetes/client/api_client.py\", line 345, in call_api\r\n    _preload_content, _request_timeout)\r\n  File \"/usr/local/lib/python3.6/site-packages/kubernetes/client/api_client.py\", line 176, in __call_api\r\n    _request_timeout=_request_timeout)\r\n  File \"/usr/local/lib/python3.6/site-packages/kubernetes/client/api_client.py\", line 366, in request\r\n    headers=headers)\r\n  File \"/usr/local/lib/python3.6/site-packages/kubernetes/client/rest.py\", line 241, in GET\r\n    query_params=query_params)\r\n  File \"/usr/local/lib/python3.6/site-packages/kubernetes/client/rest.py\", line 231, in request\r\n    raise ApiException(http_resp=r)\r\nkubernetes.client.rest.ApiException: (403)\r\nReason: Forbidden\r\nHTTP response headers: HTTPHeaderDict({'Audit-Id': 'c317f54d-de26-4f17-93ce-7e93a028b03a', 'Cache-Control': 'no-cache, private', 'Content-Type': 'application/json', 'X-Content-Type-Options': 'nosniff', 'X-Kubernetes-Pf-Flowschema-Uid': '931cd882-0bf8-4834-952a-32da3efc767d', 'X-Kubernetes-Pf-Prioritylevel-Uid': '48f2b632-2f58-42ab-a5da-f056f716d40c', 'Date': 'Tue, 15 Dec 2020 19:41:18 GMT', 'Content-Length': '392'})\r\nHTTP response body: b'{\"kind\":\"Status\",\"apiVersion\":\"v1\",\"metadata\":{},\"status\":\"Failure\",\"message\":\"machinesets.machine.openshift.io is forbidden: User \\\\\"system:serviceaccount:default:onboarding\\\\\" cannot list resource \\\\\"machinesets\\\\\" in API group \\\\\"machine.openshift.io\\\\\" in the namespace \\\\\"openshift-machine-api\\\\\"\",\"reason\":\"Forbidden\",\"details\":{\"group\":\"machine.openshift.io\",\"kind\":\"machinesets\"},\"code\":403}\\n'\r\n\r\n\r\nDuring handling of the above exception, another exception occurred:\r\n\r\nTraceback (most recent call last):\r\n  File \"/home/ec2-user/.ansible/tmp/ansible-tmp-1608061277.04-97491675688983/AnsiballZ_k8s_facts.py\", line 114, in <module>\r\n    _ansiballz_main()\r\n  File \"/home/ec2-user/.ansible/tmp/ansible-tmp-1608061277.04-97491675688983/AnsiballZ_k8s_facts.py\", line 106, in _ansiballz_main\r\n    invoke_module(zipped_mod, temp_path, ANSIBALLZ_PARAMS)\r\n  File \"/home/ec2-user/.ansible/tmp/ansible-tmp-1608061277.04-97491675688983/AnsiballZ_k8s_facts.py\", line 49, in invoke_module\r\n    imp.load_module('__main__', mod, module, MOD_DESC)\r\n  File \"/usr/lib64/python3.6/imp.py\", line 235, in load_module\r\n    return load_source(name, filename, file)\r\n  File \"/usr/lib64/python3.6/imp.py\", line 170, in load_source\r\n    module = _exec(spec, sys.modules[name])\r\n  File \"<frozen importlib._bootstrap>\", line 618, in _exec\r\n  File \"<frozen importlib._bootstrap_external>\", line 678, in exec_module\r\n  File \"<frozen importlib._bootstrap>\", line 219, in _call_with_frames_removed\r\n  File \"/tmp/ansible_k8s_facts_payload_it7b49e3/__main__.py\", line 176, in <module>\r\n  File \"/tmp/ansible_k8s_facts_payload_it7b49e3/__main__.py\", line 172, in main\r\n  File \"/tmp/ansible_k8s_facts_payload_it7b49e3/__main__.py\", line 153, in execute_module\r\n  File \"/tmp/ansible_k8s_facts_payload_it7b49e3/ansible_k8s_facts_payload.zip/ansible/module_utils/k8s/common.py\", line 206, in kubernetes_facts\r\n  File \"/usr/local/lib/python3.6/site-packages/openshift/dynamic/client.py\", line 94, in get\r\n    return self.request('get', path, **kwargs)\r\n  File \"/usr/local/lib/python3.6/site-packages/openshift/dynamic/client.py\", line 44, in inner\r\n    raise api_exception(e)\r\nopenshift.dynamic.exceptions.ForbiddenError: 403\r\nReason: Forbidden\r\nHTTP response headers: HTTPHeaderDict({'Audit-Id': 'c317f54d-de26-4f17-93ce-7e93a028b03a', 'Cache-Control': 'no-cache, private', 'Content-Type': 'application/json', 'X-Content-Type-Options': 'nosniff', 'X-Kubernetes-Pf-Flowschema-Uid': '931cd882-0bf8-4834-952a-32da3efc767d', 'X-Kubernetes-Pf-Prioritylevel-Uid': '48f2b632-2f58-42ab-a5da-f056f716d40c', 'Date': 'Tue, 15 Dec 2020 19:41:18 GMT', 'Content-Length': '392'})\r\nHTTP response body: b'{\"kind\":\"Status\",\"apiVersion\":\"v1\",\"metadata\":{},\"status\":\"Failure\",\"message\":\"machinesets.machine.openshift.io is forbidden: User \\\\\"system:serviceaccount:default:onboarding\\\\\" cannot list resource \\\\\"machinesets\\\\\" in API group \\\\\"machine.openshift.io\\\\\" in the namespace \\\\\"openshift-machine-api\\\\\"\",\"reason\":\"Forbidden\",\"details\":{\"group\":\"machine.openshift.io\",\"kind\":\"machinesets\"},\"code\":403}\\n'\r\nOriginal traceback: \r\n  File \"/usr/local/lib/python3.6/site-packages/openshift/dynamic/client.py\", line 42, in inner\r\n    resp = func(self, *args, **kwargs)\r\n\r\n  File \"/usr/local/lib/python3.6/site-packages/openshift/dynamic/client.py\", line 247, in request\r\n    _return_http_data_only=params.get('_return_http_data_only', True)\r\n\r\n  File \"/usr/local/lib/python3.6/site-packages/kubernetes/client/api_client.py\", line 345, in call_api\r\n    _preload_content, _request_timeout)\r\n\r\n  File \"/usr/local/lib/python3.6/site-packages/kubernetes/client/api_client.py\", line 176, in __call_api\r\n    _request_timeout=_request_timeout)\r\n\r\n  File \"/usr/local/lib/python3.6/site-packages/kubernetes/client/api_client.py\", line 366, in request\r\n    headers=headers)\r\n\r\n  File \"/usr/local/lib/python3.6/site-packages/kubernetes/client/rest.py\", line 241, in GET\r\n    query_params=query_params)\r\n\r\n  File \"/usr/local/lib/python3.6/site-packages/kubernetes/client/rest.py\", line 231, in request\r\n    raise ApiException(http_resp=r)\r\n\r\n", "msg": "MODULE FAILURE\nSee stdout/stderr for the exact error", "rc": 1}
fatal: [bastion-ocp4-int-qa-east]: FAILED! => {"changed": false, "module_stderr": "Shared connection to 10.211.216.213 closed.\r\n", "module_stdout": "Traceback (most recent call last):\r\n  File \"/usr/local/lib/python3.6/site-packages/openshift/dynamic/client.py\", line 42, in inner\r\n    resp = func(self, *args, **kwargs)\r\n  File \"/usr/local/lib/python3.6/site-packages/openshift/dynamic/client.py\", line 247, in request\r\n    _return_http_data_only=params.get('_return_http_data_only', True)\r\n  File \"/usr/local/lib/python3.6/site-packages/kubernetes/client/api_client.py\", line 345, in call_api\r\n    _preload_content, _request_timeout)\r\n  File \"/usr/local/lib/python3.6/site-packages/kubernetes/client/api_client.py\", line 176, in __call_api\r\n    _request_timeout=_request_timeout)\r\n  File \"/usr/local/lib/python3.6/site-packages/kubernetes/client/api_client.py\", line 366, in request\r\n    headers=headers)\r\n  File \"/usr/local/lib/python3.6/site-packages/kubernetes/client/rest.py\", line 241, in GET\r\n    query_params=query_params)\r\n  File \"/usr/local/lib/python3.6/site-packages/kubernetes/client/rest.py\", line 231, in request\r\n    raise ApiException(http_resp=r)\r\nkubernetes.client.rest.ApiException: (403)\r\nReason: Forbidden\r\nHTTP response headers: HTTPHeaderDict({'Audit-Id': '3b1284be-fc28-4aed-aa8c-f216eb927c74', 'Cache-Control': 'no-cache, private', 'Content-Type': 'application/json', 'X-Content-Type-Options': 'nosniff', 'X-Kubernetes-Pf-Flowschema-Uid': '4572e21a-6262-4a80-86f1-46a4095bb20f', 'X-Kubernetes-Pf-Prioritylevel-Uid': '3562e1f6-6ed8-4845-9e77-4725543ef340', 'Date': 'Tue, 15 Dec 2020 19:41:18 GMT', 'Content-Length': '392'})\r\nHTTP response body: b'{\"kind\":\"Status\",\"apiVersion\":\"v1\",\"metadata\":{},\"status\":\"Failure\",\"message\":\"machinesets.machine.openshift.io is forbidden: User \\\\\"system:serviceaccount:default:onboarding\\\\\" cannot list resource \\\\\"machinesets\\\\\" in API group \\\\\"machine.openshift.io\\\\\" in the namespace \\\\\"openshift-machine-api\\\\\"\",\"reason\":\"Forbidden\",\"details\":{\"group\":\"machine.openshift.io\",\"kind\":\"machinesets\"},\"code\":403}\\n'\r\n\r\n\r\nDuring handling of the above exception, another exception occurred:\r\n\r\nTraceback (most recent call last):\r\n  File \"/home/ec2-user/.ansible/tmp/ansible-tmp-1608061276.97-202442100973055/AnsiballZ_k8s_facts.py\", line 114, in <module>\r\n    _ansiballz_main()\r\n  File \"/home/ec2-user/.ansible/tmp/ansible-tmp-1608061276.97-202442100973055/AnsiballZ_k8s_facts.py\", line 106, in _ansiballz_main\r\n    invoke_module(zipped_mod, temp_path, ANSIBALLZ_PARAMS)\r\n  File \"/home/ec2-user/.ansible/tmp/ansible-tmp-1608061276.97-202442100973055/AnsiballZ_k8s_facts.py\", line 49, in invoke_module\r\n    imp.load_module('__main__', mod, module, MOD_DESC)\r\n  File \"/usr/lib64/python3.6/imp.py\", line 235, in load_module\r\n    return load_source(name, filename, file)\r\n  File \"/usr/lib64/python3.6/imp.py\", line 170, in load_source\r\n    module = _exec(spec, sys.modules[name])\r\n  File \"<frozen importlib._bootstrap>\", line 618, in _exec\r\n  File \"<frozen importlib._bootstrap_external>\", line 678, in exec_module\r\n  File \"<frozen importlib._bootstrap>\", line 219, in _call_with_frames_removed\r\n  File \"/tmp/ansible_k8s_facts_payload_h6wi7h0q/__main__.py\", line 176, in <module>\r\n  File \"/tmp/ansible_k8s_facts_payload_h6wi7h0q/__main__.py\", line 172, in main\r\n  File \"/tmp/ansible_k8s_facts_payload_h6wi7h0q/__main__.py\", line 153, in execute_module\r\n  File \"/tmp/ansible_k8s_facts_payload_h6wi7h0q/ansible_k8s_facts_payload.zip/ansible/module_utils/k8s/common.py\", line 206, in kubernetes_facts\r\n  File \"/usr/local/lib/python3.6/site-packages/openshift/dynamic/client.py\", line 94, in get\r\n    return self.request('get', path, **kwargs)\r\n  File \"/usr/local/lib/python3.6/site-packages/openshift/dynamic/client.py\", line 44, in inner\r\n    raise api_exception(e)\r\nopenshift.dynamic.exceptions.ForbiddenError: 403\r\nReason: Forbidden\r\nHTTP response headers: HTTPHeaderDict({'Audit-Id': '3b1284be-fc28-4aed-aa8c-f216eb927c74', 'Cache-Control': 'no-cache, private', 'Content-Type': 'application/json', 'X-Content-Type-Options': 'nosniff', 'X-Kubernetes-Pf-Flowschema-Uid': '4572e21a-6262-4a80-86f1-46a4095bb20f', 'X-Kubernetes-Pf-Prioritylevel-Uid': '3562e1f6-6ed8-4845-9e77-4725543ef340', 'Date': 'Tue, 15 Dec 2020 19:41:18 GMT', 'Content-Length': '392'})\r\nHTTP response body: b'{\"kind\":\"Status\",\"apiVersion\":\"v1\",\"metadata\":{},\"status\":\"Failure\",\"message\":\"machinesets.machine.openshift.io is forbidden: User \\\\\"system:serviceaccount:default:onboarding\\\\\" cannot list resource \\\\\"machinesets\\\\\" in API group \\\\\"machine.openshift.io\\\\\" in the namespace \\\\\"openshift-machine-api\\\\\"\",\"reason\":\"Forbidden\",\"details\":{\"group\":\"machine.openshift.io\",\"kind\":\"machinesets\"},\"code\":403}\\n'\r\nOriginal traceback: \r\n  File \"/usr/local/lib/python3.6/site-packages/openshift/dynamic/client.py\", line 42, in inner\r\n    resp = func(self, *args, **kwargs)\r\n\r\n  File \"/usr/local/lib/python3.6/site-packages/openshift/dynamic/client.py\", line 247, in request\r\n    _return_http_data_only=params.get('_return_http_data_only', True)\r\n\r\n  File \"/usr/local/lib/python3.6/site-packages/kubernetes/client/api_client.py\", line 345, in call_api\r\n    _preload_content, _request_timeout)\r\n\r\n  File \"/usr/local/lib/python3.6/site-packages/kubernetes/client/api_client.py\", line 176, in __call_api\r\n    _request_timeout=_request_timeout)\r\n\r\n  File \"/usr/local/lib/python3.6/site-packages/kubernetes/client/api_client.py\", line 366, in request\r\n    headers=headers)\r\n\r\n  File \"/usr/local/lib/python3.6/site-packages/kubernetes/client/rest.py\", line 241, in GET\r\n    query_params=query_params)\r\n\r\n  File \"/usr/local/lib/python3.6/site-packages/kubernetes/client/rest.py\", line 231, in request\r\n    raise ApiException(http_resp=r)\r\n\r\n", "msg": "MODULE FAILURE\nSee stdout/stderr for the exact error", "rc": 1}
fatal: [bastion-ocp4-ext-qa-west]: FAILED! => {"changed": false, "module_stderr": "Shared connection to 10.244.208.221 closed.\r\n", "module_stdout": "Traceback (most recent call last):\r\n  File \"/usr/local/lib/python3.6/site-packages/openshift/dynamic/client.py\", line 42, in inner\r\n    resp = func(self, *args, **kwargs)\r\n  File \"/usr/local/lib/python3.6/site-packages/openshift/dynamic/client.py\", line 247, in request\r\n    _return_http_data_only=params.get('_return_http_data_only', True)\r\n  File \"/usr/local/lib/python3.6/site-packages/kubernetes/client/api_client.py\", line 345, in call_api\r\n    _preload_content, _request_timeout)\r\n  File \"/usr/local/lib/python3.6/site-packages/kubernetes/client/api_client.py\", line 176, in __call_api\r\n    _request_timeout=_request_timeout)\r\n  File \"/usr/local/lib/python3.6/site-packages/kubernetes/client/api_client.py\", line 366, in request\r\n    headers=headers)\r\n  File \"/usr/local/lib/python3.6/site-packages/kubernetes/client/rest.py\", line 241, in GET\r\n    query_params=query_params)\r\n  File \"/usr/local/lib/python3.6/site-packages/kubernetes/client/rest.py\", line 231, in request\r\n    raise ApiException(http_resp=r)\r\nkubernetes.client.rest.ApiException: (403)\r\nReason: Forbidden\r\nHTTP response headers: HTTPHeaderDict({'Audit-Id': 'f8d90c3c-490c-41cf-b52d-0bc3eddc0e51', 'Cache-Control': 'no-cache, private', 'Content-Type': 'application/json', 'X-Content-Type-Options': 'nosniff', 'X-Kubernetes-Pf-Flowschema-Uid': 'ad695881-3369-42d9-895e-9ebe026239ca', 'X-Kubernetes-Pf-Prioritylevel-Uid': 'ef1d4961-983b-4966-9c67-9213307ae591', 'Date': 'Tue, 15 Dec 2020 19:41:18 GMT', 'Content-Length': '392'})\r\nHTTP response body: b'{\"kind\":\"Status\",\"apiVersion\":\"v1\",\"metadata\":{},\"status\":\"Failure\",\"message\":\"machinesets.machine.openshift.io is forbidden: User \\\\\"system:serviceaccount:default:onboarding\\\\\" cannot list resource \\\\\"machinesets\\\\\" in API group \\\\\"machine.openshift.io\\\\\" in the namespace \\\\\"openshift-machine-api\\\\\"\",\"reason\":\"Forbidden\",\"details\":{\"group\":\"machine.openshift.io\",\"kind\":\"machinesets\"},\"code\":403}\\n'\r\n\r\n\r\nDuring handling of the above exception, another exception occurred:\r\n\r\nTraceback (most recent call last):\r\n  File \"/home/ec2-user/.ansible/tmp/ansible-tmp-1608061277.02-107796541192185/AnsiballZ_k8s_facts.py\", line 114, in <module>\r\n    _ansiballz_main()\r\n  File \"/home/ec2-user/.ansible/tmp/ansible-tmp-1608061277.02-107796541192185/AnsiballZ_k8s_facts.py\", line 106, in _ansiballz_main\r\n    invoke_module(zipped_mod, temp_path, ANSIBALLZ_PARAMS)\r\n  File \"/home/ec2-user/.ansible/tmp/ansible-tmp-1608061277.02-107796541192185/AnsiballZ_k8s_facts.py\", line 49, in invoke_module\r\n    imp.load_module('__main__', mod, module, MOD_DESC)\r\n  File \"/usr/lib64/python3.6/imp.py\", line 235, in load_module\r\n    return load_source(name, filename, file)\r\n  File \"/usr/lib64/python3.6/imp.py\", line 170, in load_source\r\n    module = _exec(spec, sys.modules[name])\r\n  File \"<frozen importlib._bootstrap>\", line 618, in _exec\r\n  File \"<frozen importlib._bootstrap_external>\", line 678, in exec_module\r\n  File \"<frozen importlib._bootstrap>\", line 219, in _call_with_frames_removed\r\n  File \"/tmp/ansible_k8s_facts_payload_xij8eg0n/__main__.py\", line 176, in <module>\r\n  File \"/tmp/ansible_k8s_facts_payload_xij8eg0n/__main__.py\", line 172, in main\r\n  File \"/tmp/ansible_k8s_facts_payload_xij8eg0n/__main__.py\", line 153, in execute_module\r\n  File \"/tmp/ansible_k8s_facts_payload_xij8eg0n/ansible_k8s_facts_payload.zip/ansible/module_utils/k8s/common.py\", line 206, in kubernetes_facts\r\n  File \"/usr/local/lib/python3.6/site-packages/openshift/dynamic/client.py\", line 94, in get\r\n    return self.request('get', path, **kwargs)\r\n  File \"/usr/local/lib/python3.6/site-packages/openshift/dynamic/client.py\", line 44, in inner\r\n    raise api_exception(e)\r\nopenshift.dynamic.exceptions.ForbiddenError: 403\r\nReason: Forbidden\r\nHTTP response headers: HTTPHeaderDict({'Audit-Id': 'f8d90c3c-490c-41cf-b52d-0bc3eddc0e51', 'Cache-Control': 'no-cache, private', 'Content-Type': 'application/json', 'X-Content-Type-Options': 'nosniff', 'X-Kubernetes-Pf-Flowschema-Uid': 'ad695881-3369-42d9-895e-9ebe026239ca', 'X-Kubernetes-Pf-Prioritylevel-Uid': 'ef1d4961-983b-4966-9c67-9213307ae591', 'Date': 'Tue, 15 Dec 2020 19:41:18 GMT', 'Content-Length': '392'})\r\nHTTP response body: b'{\"kind\":\"Status\",\"apiVersion\":\"v1\",\"metadata\":{},\"status\":\"Failure\",\"message\":\"machinesets.machine.openshift.io is forbidden: User \\\\\"system:serviceaccount:default:onboarding\\\\\" cannot list resource \\\\\"machinesets\\\\\" in API group \\\\\"machine.openshift.io\\\\\" in the namespace \\\\\"openshift-machine-api\\\\\"\",\"reason\":\"Forbidden\",\"details\":{\"group\":\"machine.openshift.io\",\"kind\":\"machinesets\"},\"code\":403}\\n'\r\nOriginal traceback: \r\n  File \"/usr/local/lib/python3.6/site-packages/openshift/dynamic/client.py\", line 42, in inner\r\n    resp = func(self, *args, **kwargs)\r\n\r\n  File \"/usr/local/lib/python3.6/site-packages/openshift/dynamic/client.py\", line 247, in request\r\n    _return_http_data_only=params.get('_return_http_data_only', True)\r\n\r\n  File \"/usr/local/lib/python3.6/site-packages/kubernetes/client/api_client.py\", line 345, in call_api\r\n    _preload_content, _request_timeout)\r\n\r\n  File \"/usr/local/lib/python3.6/site-packages/kubernetes/client/api_client.py\", line 176, in __call_api\r\n    _request_timeout=_request_timeout)\r\n\r\n  File \"/usr/local/lib/python3.6/site-packages/kubernetes/client/api_client.py\", line 366, in request\r\n    headers=headers)\r\n\r\n  File \"/usr/local/lib/python3.6/site-packages/kubernetes/client/rest.py\", line 241, in GET\r\n    query_params=query_params)\r\n\r\n  File \"/usr/local/lib/python3.6/site-packages/kubernetes/client/rest.py\", line 231, in request\r\n    raise ApiException(http_resp=r)\r\n\r\n", "msg": "MODULE FAILURE\nSee stdout/stderr for the exact error", "rc": 1}
fatal: [bastion-ocp4-int-dev-test]: FAILED! => {"changed": false, "module_stderr": "Shared connection to 10.244.161.21 closed.\r\n", "module_stdout": "Traceback (most recent call last):\r\n  File \"/usr/local/lib/python3.6/site-packages/openshift/dynamic/client.py\", line 42, in inner\r\n    resp = func(self, *args, **kwargs)\r\n  File \"/usr/local/lib/python3.6/site-packages/openshift/dynamic/client.py\", line 245, in request\r\n    _return_http_data_only=params.get('_return_http_data_only', True)\r\n  File \"/usr/local/lib/python3.6/site-packages/kubernetes/client/api_client.py\", line 345, in call_api\r\n    _preload_content, _request_timeout)\r\n  File \"/usr/local/lib/python3.6/site-packages/kubernetes/client/api_client.py\", line 176, in __call_api\r\n    _request_timeout=_request_timeout)\r\n  File \"/usr/local/lib/python3.6/site-packages/kubernetes/client/api_client.py\", line 366, in request\r\n    headers=headers)\r\n  File \"/usr/local/lib/python3.6/site-packages/kubernetes/client/rest.py\", line 241, in GET\r\n    query_params=query_params)\r\n  File \"/usr/local/lib/python3.6/site-packages/kubernetes/client/rest.py\", line 231, in request\r\n    raise ApiException(http_resp=r)\r\nkubernetes.client.rest.ApiException: (403)\r\nReason: Forbidden\r\nHTTP response headers: HTTPHeaderDict({'Audit-Id': '35d1fa00-8dba-4d11-98d0-0c40f0cc0022', 'Cache-Control': 'no-cache, private', 'Content-Type': 'application/json', 'X-Content-Type-Options': 'nosniff', 'X-Kubernetes-Pf-Flowschema-Uid': '8ab1abbc-8429-4e04-a778-a93f26992f9d', 'X-Kubernetes-Pf-Prioritylevel-Uid': 'f6361168-9c55-4ce0-a4b1-bd15857922b1', 'Date': 'Tue, 15 Dec 2020 19:41:18 GMT', 'Content-Length': '392'})\r\nHTTP response body: b'{\"kind\":\"Status\",\"apiVersion\":\"v1\",\"metadata\":{},\"status\":\"Failure\",\"message\":\"machinesets.machine.openshift.io is forbidden: User \\\\\"system:serviceaccount:default:onboarding\\\\\" cannot list resource \\\\\"machinesets\\\\\" in API group \\\\\"machine.openshift.io\\\\\" in the namespace \\\\\"openshift-machine-api\\\\\"\",\"reason\":\"Forbidden\",\"details\":{\"group\":\"machine.openshift.io\",\"kind\":\"machinesets\"},\"code\":403}\\n'\r\n\r\n\r\nDuring handling of the above exception, another exception occurred:\r\n\r\nTraceback (most recent call last):\r\n  File \"/home/ec2-user/.ansible/tmp/ansible-tmp-1608061276.99-73566180247955/AnsiballZ_k8s_facts.py\", line 114, in <module>\r\n    _ansiballz_main()\r\n  File \"/home/ec2-user/.ansible/tmp/ansible-tmp-1608061276.99-73566180247955/AnsiballZ_k8s_facts.py\", line 106, in _ansiballz_main\r\n    invoke_module(zipped_mod, temp_path, ANSIBALLZ_PARAMS)\r\n  File \"/home/ec2-user/.ansible/tmp/ansible-tmp-1608061276.99-73566180247955/AnsiballZ_k8s_facts.py\", line 49, in invoke_module\r\n    imp.load_module('__main__', mod, module, MOD_DESC)\r\n  File \"/usr/lib64/python3.6/imp.py\", line 235, in load_module\r\n    return load_source(name, filename, file)\r\n  File \"/usr/lib64/python3.6/imp.py\", line 170, in load_source\r\n    module = _exec(spec, sys.modules[name])\r\n  File \"<frozen importlib._bootstrap>\", line 618, in _exec\r\n  File \"<frozen importlib._bootstrap_external>\", line 678, in exec_module\r\n  File \"<frozen importlib._bootstrap>\", line 219, in _call_with_frames_removed\r\n  File \"/tmp/ansible_k8s_facts_payload_09jdkn20/__main__.py\", line 176, in <module>\r\n  File \"/tmp/ansible_k8s_facts_payload_09jdkn20/__main__.py\", line 172, in main\r\n  File \"/tmp/ansible_k8s_facts_payload_09jdkn20/__main__.py\", line 153, in execute_module\r\n  File \"/tmp/ansible_k8s_facts_payload_09jdkn20/ansible_k8s_facts_payload.zip/ansible/module_utils/k8s/common.py\", line 206, in kubernetes_facts\r\n  File \"/usr/local/lib/python3.6/site-packages/openshift/dynamic/client.py\", line 94, in get\r\n    return self.request('get', path, **kwargs)\r\n  File \"/usr/local/lib/python3.6/site-packages/openshift/dynamic/client.py\", line 44, in inner\r\n    raise api_exception(e)\r\nopenshift.dynamic.exceptions.ForbiddenError: 403\r\nReason: Forbidden\r\nHTTP response headers: HTTPHeaderDict({'Audit-Id': '35d1fa00-8dba-4d11-98d0-0c40f0cc0022', 'Cache-Control': 'no-cache, private', 'Content-Type': 'application/json', 'X-Content-Type-Options': 'nosniff', 'X-Kubernetes-Pf-Flowschema-Uid': '8ab1abbc-8429-4e04-a778-a93f26992f9d', 'X-Kubernetes-Pf-Prioritylevel-Uid': 'f6361168-9c55-4ce0-a4b1-bd15857922b1', 'Date': 'Tue, 15 Dec 2020 19:41:18 GMT', 'Content-Length': '392'})\r\nHTTP response body: b'{\"kind\":\"Status\",\"apiVersion\":\"v1\",\"metadata\":{},\"status\":\"Failure\",\"message\":\"machinesets.machine.openshift.io is forbidden: User \\\\\"system:serviceaccount:default:onboarding\\\\\" cannot list resource \\\\\"machinesets\\\\\" in API group \\\\\"machine.openshift.io\\\\\" in the namespace \\\\\"openshift-machine-api\\\\\"\",\"reason\":\"Forbidden\",\"details\":{\"group\":\"machine.openshift.io\",\"kind\":\"machinesets\"},\"code\":403}\\n'\r\nOriginal traceback: \r\n  File \"/usr/local/lib/python3.6/site-packages/openshift/dynamic/client.py\", line 42, in inner\r\n    resp = func(self, *args, **kwargs)\r\n\r\n  File \"/usr/local/lib/python3.6/site-packages/openshift/dynamic/client.py\", line 245, in request\r\n    _return_http_data_only=params.get('_return_http_data_only', True)\r\n\r\n  File \"/usr/local/lib/python3.6/site-packages/kubernetes/client/api_client.py\", line 345, in call_api\r\n    _preload_content, _request_timeout)\r\n\r\n  File \"/usr/local/lib/python3.6/site-packages/kubernetes/client/api_client.py\", line 176, in __call_api\r\n    _request_timeout=_request_timeout)\r\n\r\n  File \"/usr/local/lib/python3.6/site-packages/kubernetes/client/api_client.py\", line 366, in request\r\n    headers=headers)\r\n\r\n  File \"/usr/local/lib/python3.6/site-packages/kubernetes/client/rest.py\", line 241, in GET\r\n    query_params=query_params)\r\n\r\n  File \"/usr/local/lib/python3.6/site-packages/kubernetes/client/rest.py\", line 231, in request\r\n    raise ApiException(http_resp=r)\r\n\r\n", "msg": "MODULE FAILURE\nSee stdout/stderr for the exact error", "rc": 1}
fatal: [bastion-ocp4-ext-dev-east]: FAILED! => {"changed": false, "module_stderr": "Shared connection to 10.211.152.252 closed.\r\n", "module_stdout": "Traceback (most recent call last):\r\n  File \"/usr/local/lib/python3.6/site-packages/openshift/dynamic/client.py\", line 42, in inner\r\n    resp = func(self, *args, **kwargs)\r\n  File \"/usr/local/lib/python3.6/site-packages/openshift/dynamic/client.py\", line 247, in request\r\n    _return_http_data_only=params.get('_return_http_data_only', True)\r\n  File \"/usr/local/lib/python3.6/site-packages/kubernetes/client/api_client.py\", line 345, in call_api\r\n    _preload_content, _request_timeout)\r\n  File \"/usr/local/lib/python3.6/site-packages/kubernetes/client/api_client.py\", line 176, in __call_api\r\n    _request_timeout=_request_timeout)\r\n  File \"/usr/local/lib/python3.6/site-packages/kubernetes/client/api_client.py\", line 366, in request\r\n    headers=headers)\r\n  File \"/usr/local/lib/python3.6/site-packages/kubernetes/client/rest.py\", line 241, in GET\r\n    query_params=query_params)\r\n  File \"/usr/local/lib/python3.6/site-packages/kubernetes/client/rest.py\", line 231, in request\r\n    raise ApiException(http_resp=r)\r\nkubernetes.client.rest.ApiException: (403)\r\nReason: Forbidden\r\nHTTP response headers: HTTPHeaderDict({'Audit-Id': '70da395d-4789-47cc-9cf8-040545f33866', 'Cache-Control': 'no-cache, private', 'Content-Type': 'application/json', 'X-Content-Type-Options': 'nosniff', 'X-Kubernetes-Pf-Flowschema-Uid': '5a3baec3-6ca5-406f-aa66-8b96d5240766', 'X-Kubernetes-Pf-Prioritylevel-Uid': '1915dfe9-df10-4911-82da-991af6c8e422', 'Date': 'Tue, 15 Dec 2020 19:41:19 GMT', 'Content-Length': '392'})\r\nHTTP response body: b'{\"kind\":\"Status\",\"apiVersion\":\"v1\",\"metadata\":{},\"status\":\"Failure\",\"message\":\"machinesets.machine.openshift.io is forbidden: User \\\\\"system:serviceaccount:default:onboarding\\\\\" cannot list resource \\\\\"machinesets\\\\\" in API group \\\\\"machine.openshift.io\\\\\" in the namespace \\\\\"openshift-machine-api\\\\\"\",\"reason\":\"Forbidden\",\"details\":{\"group\":\"machine.openshift.io\",\"kind\":\"machinesets\"},\"code\":403}\\n'\r\n\r\n\r\nDuring handling of the above exception, another exception occurred:\r\n\r\nTraceback (most recent call last):\r\n  File \"/home/ec2-user/.ansible/tmp/ansible-tmp-1608061278.68-184778065654900/AnsiballZ_k8s_facts.py\", line 114, in <module>\r\n    _ansiballz_main()\r\n  File \"/home/ec2-user/.ansible/tmp/ansible-tmp-1608061278.68-184778065654900/AnsiballZ_k8s_facts.py\", line 106, in _ansiballz_main\r\n    invoke_module(zipped_mod, temp_path, ANSIBALLZ_PARAMS)\r\n  File \"/home/ec2-user/.ansible/tmp/ansible-tmp-1608061278.68-184778065654900/AnsiballZ_k8s_facts.py\", line 49, in invoke_module\r\n    imp.load_module('__main__', mod, module, MOD_DESC)\r\n  File \"/usr/lib64/python3.6/imp.py\", line 235, in load_module\r\n    return load_source(name, filename, file)\r\n  File \"/usr/lib64/python3.6/imp.py\", line 170, in load_source\r\n    module = _exec(spec, sys.modules[name])\r\n  File \"<frozen importlib._bootstrap>\", line 618, in _exec\r\n  File \"<frozen importlib._bootstrap_external>\", line 678, in exec_module\r\n  File \"<frozen importlib._bootstrap>\", line 219, in _call_with_frames_removed\r\n  File \"/tmp/ansible_k8s_facts_payload_89ewwl1c/__main__.py\", line 176, in <module>\r\n  File \"/tmp/ansible_k8s_facts_payload_89ewwl1c/__main__.py\", line 172, in main\r\n  File \"/tmp/ansible_k8s_facts_payload_89ewwl1c/__main__.py\", line 153, in execute_module\r\n  File \"/tmp/ansible_k8s_facts_payload_89ewwl1c/ansible_k8s_facts_payload.zip/ansible/module_utils/k8s/common.py\", line 206, in kubernetes_facts\r\n  File \"/usr/local/lib/python3.6/site-packages/openshift/dynamic/client.py\", line 94, in get\r\n    return self.request('get', path, **kwargs)\r\n  File \"/usr/local/lib/python3.6/site-packages/openshift/dynamic/client.py\", line 44, in inner\r\n    raise api_exception(e)\r\nopenshift.dynamic.exceptions.ForbiddenError: 403\r\nReason: Forbidden\r\nHTTP response headers: HTTPHeaderDict({'Audit-Id': '70da395d-4789-47cc-9cf8-040545f33866', 'Cache-Control': 'no-cache, private', 'Content-Type': 'application/json', 'X-Content-Type-Options': 'nosniff', 'X-Kubernetes-Pf-Flowschema-Uid': '5a3baec3-6ca5-406f-aa66-8b96d5240766', 'X-Kubernetes-Pf-Prioritylevel-Uid': '1915dfe9-df10-4911-82da-991af6c8e422', 'Date': 'Tue, 15 Dec 2020 19:41:19 GMT', 'Content-Length': '392'})\r\nHTTP response body: b'{\"kind\":\"Status\",\"apiVersion\":\"v1\",\"metadata\":{},\"status\":\"Failure\",\"message\":\"machinesets.machine.openshift.io is forbidden: User \\\\\"system:serviceaccount:default:onboarding\\\\\" cannot list resource \\\\\"machinesets\\\\\" in API group \\\\\"machine.openshift.io\\\\\" in the namespace \\\\\"openshift-machine-api\\\\\"\",\"reason\":\"Forbidden\",\"details\":{\"group\":\"machine.openshift.io\",\"kind\":\"machinesets\"},\"code\":403}\\n'\r\nOriginal traceback: \r\n  File \"/usr/local/lib/python3.6/site-packages/openshift/dynamic/client.py\", line 42, in inner\r\n    resp = func(self, *args, **kwargs)\r\n\r\n  File \"/usr/local/lib/python3.6/site-packages/openshift/dynamic/client.py\", line 247, in request\r\n    _return_http_data_only=params.get('_return_http_data_only', True)\r\n\r\n  File \"/usr/local/lib/python3.6/site-packages/kubernetes/client/api_client.py\", line 345, in call_api\r\n    _preload_content, _request_timeout)\r\n\r\n  File \"/usr/local/lib/python3.6/site-packages/kubernetes/client/api_client.py\", line 176, in __call_api\r\n    _request_timeout=_request_timeout)\r\n\r\n  File \"/usr/local/lib/python3.6/site-packages/kubernetes/client/api_client.py\", line 366, in request\r\n    headers=headers)\r\n\r\n  File \"/usr/local/lib/python3.6/site-packages/kubernetes/client/rest.py\", line 241, in GET\r\n    query_params=query_params)\r\n\r\n  File \"/usr/local/lib/python3.6/site-packages/kubernetes/client/rest.py\", line 231, in request\r\n    raise ApiException(http_resp=r)\r\n\r\n", "msg": "MODULE FAILURE\nSee stdout/stderr for the exact error", "rc": 1}
fatal: [bastion-ocp4-int-dev-west]: FAILED! => {"changed": false, "module_stderr": "Shared connection to 10.244.161.6 closed.\r\n", "module_stdout": "Traceback (most recent call last):\r\n  File \"/usr/local/lib/python3.6/site-packages/openshift/dynamic/client.py\", line 42, in inner\r\n    resp = func(self, *args, **kwargs)\r\n  File \"/usr/local/lib/python3.6/site-packages/openshift/dynamic/client.py\", line 247, in request\r\n    _return_http_data_only=params.get('_return_http_data_only', True)\r\n  File \"/usr/local/lib/python3.6/site-packages/kubernetes/client/api_client.py\", line 345, in call_api\r\n    _preload_content, _request_timeout)\r\n  File \"/usr/local/lib/python3.6/site-packages/kubernetes/client/api_client.py\", line 176, in __call_api\r\n    _request_timeout=_request_timeout)\r\n  File \"/usr/local/lib/python3.6/site-packages/kubernetes/client/api_client.py\", line 366, in request\r\n    headers=headers)\r\n  File \"/usr/local/lib/python3.6/site-packages/kubernetes/client/rest.py\", line 241, in GET\r\n    query_params=query_params)\r\n  File \"/usr/local/lib/python3.6/site-packages/kubernetes/client/rest.py\", line 231, in request\r\n    raise ApiException(http_resp=r)\r\nkubernetes.client.rest.ApiException: (403)\r\nReason: Forbidden\r\nHTTP response headers: HTTPHeaderDict({'Audit-Id': '499e8e8c-c90e-43cc-813e-6db82acbd141', 'Cache-Control': 'no-cache, private', 'Content-Type': 'application/json', 'X-Content-Type-Options': 'nosniff', 'X-Kubernetes-Pf-Flowschema-Uid': '52a22417-2f37-40ac-ab52-9082bb8b0a28', 'X-Kubernetes-Pf-Prioritylevel-Uid': 'e0d33633-5444-429a-a7c9-ca9203bda791', 'Date': 'Tue, 15 Dec 2020 19:41:20 GMT', 'Content-Length': '392'})\r\nHTTP response body: b'{\"kind\":\"Status\",\"apiVersion\":\"v1\",\"metadata\":{},\"status\":\"Failure\",\"message\":\"machinesets.machine.openshift.io is forbidden: User \\\\\"system:serviceaccount:default:onboarding\\\\\" cannot list resource \\\\\"machinesets\\\\\" in API group \\\\\"machine.openshift.io\\\\\" in the namespace \\\\\"openshift-machine-api\\\\\"\",\"reason\":\"Forbidden\",\"details\":{\"group\":\"machine.openshift.io\",\"kind\":\"machinesets\"},\"code\":403}\\n'\r\n\r\n\r\nDuring handling of the above exception, another exception occurred:\r\n\r\nTraceback (most recent call last):\r\n  File \"/home/ec2-user/.ansible/tmp/ansible-tmp-1608061278.85-230193206475028/AnsiballZ_k8s_facts.py\", line 114, in <module>\r\n    _ansiballz_main()\r\n  File \"/home/ec2-user/.ansible/tmp/ansible-tmp-1608061278.85-230193206475028/AnsiballZ_k8s_facts.py\", line 106, in _ansiballz_main\r\n    invoke_module(zipped_mod, temp_path, ANSIBALLZ_PARAMS)\r\n  File \"/home/ec2-user/.ansible/tmp/ansible-tmp-1608061278.85-230193206475028/AnsiballZ_k8s_facts.py\", line 49, in invoke_module\r\n    imp.load_module('__main__', mod, module, MOD_DESC)\r\n  File \"/usr/lib64/python3.6/imp.py\", line 235, in load_module\r\n    return load_source(name, filename, file)\r\n  File \"/usr/lib64/python3.6/imp.py\", line 170, in load_source\r\n    module = _exec(spec, sys.modules[name])\r\n  File \"<frozen importlib._bootstrap>\", line 618, in _exec\r\n  File \"<frozen importlib._bootstrap_external>\", line 678, in exec_module\r\n  File \"<frozen importlib._bootstrap>\", line 219, in _call_with_frames_removed\r\n  File \"/tmp/ansible_k8s_facts_payload_l592zkkm/__main__.py\", line 176, in <module>\r\n  File \"/tmp/ansible_k8s_facts_payload_l592zkkm/__main__.py\", line 172, in main\r\n  File \"/tmp/ansible_k8s_facts_payload_l592zkkm/__main__.py\", line 153, in execute_module\r\n  File \"/tmp/ansible_k8s_facts_payload_l592zkkm/ansible_k8s_facts_payload.zip/ansible/module_utils/k8s/common.py\", line 206, in kubernetes_facts\r\n  File \"/usr/local/lib/python3.6/site-packages/openshift/dynamic/client.py\", line 94, in get\r\n    return self.request('get', path, **kwargs)\r\n  File \"/usr/local/lib/python3.6/site-packages/openshift/dynamic/client.py\", line 44, in inner\r\n    raise api_exception(e)\r\nopenshift.dynamic.exceptions.ForbiddenError: 403\r\nReason: Forbidden\r\nHTTP response headers: HTTPHeaderDict({'Audit-Id': '499e8e8c-c90e-43cc-813e-6db82acbd141', 'Cache-Control': 'no-cache, private', 'Content-Type': 'application/json', 'X-Content-Type-Options': 'nosniff', 'X-Kubernetes-Pf-Flowschema-Uid': '52a22417-2f37-40ac-ab52-9082bb8b0a28', 'X-Kubernetes-Pf-Prioritylevel-Uid': 'e0d33633-5444-429a-a7c9-ca9203bda791', 'Date': 'Tue, 15 Dec 2020 19:41:20 GMT', 'Content-Length': '392'})\r\nHTTP response body: b'{\"kind\":\"Status\",\"apiVersion\":\"v1\",\"metadata\":{},\"status\":\"Failure\",\"message\":\"machinesets.machine.openshift.io is forbidden: User \\\\\"system:serviceaccount:default:onboarding\\\\\" cannot list resource \\\\\"machinesets\\\\\" in API group \\\\\"machine.openshift.io\\\\\" in the namespace \\\\\"openshift-machine-api\\\\\"\",\"reason\":\"Forbidden\",\"details\":{\"group\":\"machine.openshift.io\",\"kind\":\"machinesets\"},\"code\":403}\\n'\r\nOriginal traceback: \r\n  File \"/usr/local/lib/python3.6/site-packages/openshift/dynamic/client.py\", line 42, in inner\r\n    resp = func(self, *args, **kwargs)\r\n\r\n  File \"/usr/local/lib/python3.6/site-packages/openshift/dynamic/client.py\", line 247, in request\r\n    _return_http_data_only=params.get('_return_http_data_only', True)\r\n\r\n  File \"/usr/local/lib/python3.6/site-packages/kubernetes/client/api_client.py\", line 345, in call_api\r\n    _preload_content, _request_timeout)\r\n\r\n  File \"/usr/local/lib/python3.6/site-packages/kubernetes/client/api_client.py\", line 176, in __call_api\r\n    _request_timeout=_request_timeout)\r\n\r\n  File \"/usr/local/lib/python3.6/site-packages/kubernetes/client/api_client.py\", line 366, in request\r\n    headers=headers)\r\n\r\n  File \"/usr/local/lib/python3.6/site-packages/kubernetes/client/rest.py\", line 241, in GET\r\n    query_params=query_params)\r\n\r\n  File \"/usr/local/lib/python3.6/site-packages/kubernetes/client/rest.py\", line 231, in request\r\n    raise ApiException(http_resp=r)\r\n\r\n", "msg": "MODULE FAILURE\nSee stdout/stderr for the exact error", "rc": 1}
fatal: [bastion-ocp4-ext-dev-west]: FAILED! => {"changed": false, "module_stderr": "Shared connection to 10.244.154.48 closed.\r\n", "module_stdout": "Traceback (most recent call last):\r\n  File \"/usr/local/lib/python3.6/site-packages/openshift/dynamic/client.py\", line 42, in inner\r\n    resp = func(self, *args, **kwargs)\r\n  File \"/usr/local/lib/python3.6/site-packages/openshift/dynamic/client.py\", line 247, in request\r\n    _return_http_data_only=params.get('_return_http_data_only', True)\r\n  File \"/usr/local/lib/python3.6/site-packages/kubernetes/client/api_client.py\", line 345, in call_api\r\n    _preload_content, _request_timeout)\r\n  File \"/usr/local/lib/python3.6/site-packages/kubernetes/client/api_client.py\", line 176, in __call_api\r\n    _request_timeout=_request_timeout)\r\n  File \"/usr/local/lib/python3.6/site-packages/kubernetes/client/api_client.py\", line 366, in request\r\n    headers=headers)\r\n  File \"/usr/local/lib/python3.6/site-packages/kubernetes/client/rest.py\", line 241, in GET\r\n    query_params=query_params)\r\n  File \"/usr/local/lib/python3.6/site-packages/kubernetes/client/rest.py\", line 231, in request\r\n    raise ApiException(http_resp=r)\r\nkubernetes.client.rest.ApiException: (403)\r\nReason: Forbidden\r\nHTTP response headers: HTTPHeaderDict({'Audit-Id': 'f9abe7ae-7b01-4b73-bd6f-f73cdab12a70', 'Cache-Control': 'no-cache, private', 'Content-Type': 'application/json', 'X-Content-Type-Options': 'nosniff', 'X-Kubernetes-Pf-Flowschema-Uid': '47e4ec68-1eba-4e16-b1e8-68f49a4e9cfe', 'X-Kubernetes-Pf-Prioritylevel-Uid': '0e4317ef-0f00-4a05-b29b-ed54d7efec46', 'Date': 'Tue, 15 Dec 2020 19:41:20 GMT', 'Content-Length': '392'})\r\nHTTP response body: b'{\"kind\":\"Status\",\"apiVersion\":\"v1\",\"metadata\":{},\"status\":\"Failure\",\"message\":\"machinesets.machine.openshift.io is forbidden: User \\\\\"system:serviceaccount:default:onboarding\\\\\" cannot list resource \\\\\"machinesets\\\\\" in API group \\\\\"machine.openshift.io\\\\\" in the namespace \\\\\"openshift-machine-api\\\\\"\",\"reason\":\"Forbidden\",\"details\":{\"group\":\"machine.openshift.io\",\"kind\":\"machinesets\"},\"code\":403}\\n'\r\n\r\n\r\nDuring handling of the above exception, another exception occurred:\r\n\r\nTraceback (most recent call last):\r\n  File \"/home/ec2-user/.ansible/tmp/ansible-tmp-1608061278.79-143381187682496/AnsiballZ_k8s_facts.py\", line 114, in <module>\r\n    _ansiballz_main()\r\n  File \"/home/ec2-user/.ansible/tmp/ansible-tmp-1608061278.79-143381187682496/AnsiballZ_k8s_facts.py\", line 106, in _ansiballz_main\r\n    invoke_module(zipped_mod, temp_path, ANSIBALLZ_PARAMS)\r\n  File \"/home/ec2-user/.ansible/tmp/ansible-tmp-1608061278.79-143381187682496/AnsiballZ_k8s_facts.py\", line 49, in invoke_module\r\n    imp.load_module('__main__', mod, module, MOD_DESC)\r\n  File \"/usr/lib64/python3.6/imp.py\", line 235, in load_module\r\n    return load_source(name, filename, file)\r\n  File \"/usr/lib64/python3.6/imp.py\", line 170, in load_source\r\n    module = _exec(spec, sys.modules[name])\r\n  File \"<frozen importlib._bootstrap>\", line 618, in _exec\r\n  File \"<frozen importlib._bootstrap_external>\", line 678, in exec_module\r\n  File \"<frozen importlib._bootstrap>\", line 219, in _call_with_frames_removed\r\n  File \"/tmp/ansible_k8s_facts_payload_1exunj0m/__main__.py\", line 176, in <module>\r\n  File \"/tmp/ansible_k8s_facts_payload_1exunj0m/__main__.py\", line 172, in main\r\n  File \"/tmp/ansible_k8s_facts_payload_1exunj0m/__main__.py\", line 153, in execute_module\r\n  File \"/tmp/ansible_k8s_facts_payload_1exunj0m/ansible_k8s_facts_payload.zip/ansible/module_utils/k8s/common.py\", line 206, in kubernetes_facts\r\n  File \"/usr/local/lib/python3.6/site-packages/openshift/dynamic/client.py\", line 94, in get\r\n    return self.request('get', path, **kwargs)\r\n  File \"/usr/local/lib/python3.6/site-packages/openshift/dynamic/client.py\", line 44, in inner\r\n    raise api_exception(e)\r\nopenshift.dynamic.exceptions.ForbiddenError: 403\r\nReason: Forbidden\r\nHTTP response headers: HTTPHeaderDict({'Audit-Id': 'f9abe7ae-7b01-4b73-bd6f-f73cdab12a70', 'Cache-Control': 'no-cache, private', 'Content-Type': 'application/json', 'X-Content-Type-Options': 'nosniff', 'X-Kubernetes-Pf-Flowschema-Uid': '47e4ec68-1eba-4e16-b1e8-68f49a4e9cfe', 'X-Kubernetes-Pf-Prioritylevel-Uid': '0e4317ef-0f00-4a05-b29b-ed54d7efec46', 'Date': 'Tue, 15 Dec 2020 19:41:20 GMT', 'Content-Length': '392'})\r\nHTTP response body: b'{\"kind\":\"Status\",\"apiVersion\":\"v1\",\"metadata\":{},\"status\":\"Failure\",\"message\":\"machinesets.machine.openshift.io is forbidden: User \\\\\"system:serviceaccount:default:onboarding\\\\\" cannot list resource \\\\\"machinesets\\\\\" in API group \\\\\"machine.openshift.io\\\\\" in the namespace \\\\\"openshift-machine-api\\\\\"\",\"reason\":\"Forbidden\",\"details\":{\"group\":\"machine.openshift.io\",\"kind\":\"machinesets\"},\"code\":403}\\n'\r\nOriginal traceback: \r\n  File \"/usr/local/lib/python3.6/site-packages/openshift/dynamic/client.py\", line 42, in inner\r\n    resp = func(self, *args, **kwargs)\r\n\r\n  File \"/usr/local/lib/python3.6/site-packages/openshift/dynamic/client.py\", line 247, in request\r\n    _return_http_data_only=params.get('_return_http_data_only', True)\r\n\r\n  File \"/usr/local/lib/python3.6/site-packages/kubernetes/client/api_client.py\", line 345, in call_api\r\n    _preload_content, _request_timeout)\r\n\r\n  File \"/usr/local/lib/python3.6/site-packages/kubernetes/client/api_client.py\", line 176, in __call_api\r\n    _request_timeout=_request_timeout)\r\n\r\n  File \"/usr/local/lib/python3.6/site-packages/kubernetes/client/api_client.py\", line 366, in request\r\n    headers=headers)\r\n\r\n  File \"/usr/local/lib/python3.6/site-packages/kubernetes/client/rest.py\", line 241, in GET\r\n    query_params=query_params)\r\n\r\n  File \"/usr/local/lib/python3.6/site-packages/kubernetes/client/rest.py\", line 231, in request\r\n    raise ApiException(http_resp=r)\r\n\r\n", "msg": "MODULE FAILURE\nSee stdout/stderr for the exact error", "rc": 1}
fatal: [bastion-ocp4-int-qa-west]: FAILED! => {"changed": false, "module_stderr": "Shared connection to 10.244.216.212 closed.\r\n", "module_stdout": "Traceback (most recent call last):\r\n  File \"/usr/local/lib/python3.6/site-packages/openshift/dynamic/client.py\", line 42, in inner\r\n    resp = func(self, *args, **kwargs)\r\n  File \"/usr/local/lib/python3.6/site-packages/openshift/dynamic/client.py\", line 247, in request\r\n    _return_http_data_only=params.get('_return_http_data_only', True)\r\n  File \"/usr/local/lib/python3.6/site-packages/kubernetes/client/api_client.py\", line 345, in call_api\r\n    _preload_content, _request_timeout)\r\n  File \"/usr/local/lib/python3.6/site-packages/kubernetes/client/api_client.py\", line 176, in __call_api\r\n    _request_timeout=_request_timeout)\r\n  File \"/usr/local/lib/python3.6/site-packages/kubernetes/client/api_client.py\", line 366, in request\r\n    headers=headers)\r\n  File \"/usr/local/lib/python3.6/site-packages/kubernetes/client/rest.py\", line 241, in GET\r\n    query_params=query_params)\r\n  File \"/usr/local/lib/python3.6/site-packages/kubernetes/client/rest.py\", line 231, in request\r\n    raise ApiException(http_resp=r)\r\nkubernetes.client.rest.ApiException: (403)\r\nReason: Forbidden\r\nHTTP response headers: HTTPHeaderDict({'Audit-Id': '996ed046-f740-41c1-b595-bfa8fd027c5a', 'Cache-Control': 'no-cache, private', 'Content-Type': 'application/json', 'X-Content-Type-Options': 'nosniff', 'X-Kubernetes-Pf-Flowschema-Uid': '1618daa5-11f3-48e2-a78a-c4bd85946f89', 'X-Kubernetes-Pf-Prioritylevel-Uid': 'e69797fa-2560-4952-9d6b-c2c49a120b33', 'Date': 'Tue, 15 Dec 2020 19:41:20 GMT', 'Content-Length': '392'})\r\nHTTP response body: b'{\"kind\":\"Status\",\"apiVersion\":\"v1\",\"metadata\":{},\"status\":\"Failure\",\"message\":\"machinesets.machine.openshift.io is forbidden: User \\\\\"system:serviceaccount:default:onboarding\\\\\" cannot list resource \\\\\"machinesets\\\\\" in API group \\\\\"machine.openshift.io\\\\\" in the namespace \\\\\"openshift-machine-api\\\\\"\",\"reason\":\"Forbidden\",\"details\":{\"group\":\"machine.openshift.io\",\"kind\":\"machinesets\"},\"code\":403}\\n'\r\n\r\n\r\nDuring handling of the above exception, another exception occurred:\r\n\r\nTraceback (most recent call last):\r\n  File \"/home/ec2-user/.ansible/tmp/ansible-tmp-1608061279.21-204456207233176/AnsiballZ_k8s_facts.py\", line 114, in <module>\r\n    _ansiballz_main()\r\n  File \"/home/ec2-user/.ansible/tmp/ansible-tmp-1608061279.21-204456207233176/AnsiballZ_k8s_facts.py\", line 106, in _ansiballz_main\r\n    invoke_module(zipped_mod, temp_path, ANSIBALLZ_PARAMS)\r\n  File \"/home/ec2-user/.ansible/tmp/ansible-tmp-1608061279.21-204456207233176/AnsiballZ_k8s_facts.py\", line 49, in invoke_module\r\n    imp.load_module('__main__', mod, module, MOD_DESC)\r\n  File \"/usr/lib64/python3.6/imp.py\", line 235, in load_module\r\n    return load_source(name, filename, file)\r\n  File \"/usr/lib64/python3.6/imp.py\", line 170, in load_source\r\n    module = _exec(spec, sys.modules[name])\r\n  File \"<frozen importlib._bootstrap>\", line 618, in _exec\r\n  File \"<frozen importlib._bootstrap_external>\", line 678, in exec_module\r\n  File \"<frozen importlib._bootstrap>\", line 219, in _call_with_frames_removed\r\n  File \"/tmp/ansible_k8s_facts_payload_b74tqa6q/__main__.py\", line 176, in <module>\r\n  File \"/tmp/ansible_k8s_facts_payload_b74tqa6q/__main__.py\", line 172, in main\r\n  File \"/tmp/ansible_k8s_facts_payload_b74tqa6q/__main__.py\", line 153, in execute_module\r\n  File \"/tmp/ansible_k8s_facts_payload_b74tqa6q/ansible_k8s_facts_payload.zip/ansible/module_utils/k8s/common.py\", line 206, in kubernetes_facts\r\n  File \"/usr/local/lib/python3.6/site-packages/openshift/dynamic/client.py\", line 94, in get\r\n    return self.request('get', path, **kwargs)\r\n  File \"/usr/local/lib/python3.6/site-packages/openshift/dynamic/client.py\", line 44, in inner\r\n    raise api_exception(e)\r\nopenshift.dynamic.exceptions.ForbiddenError: 403\r\nReason: Forbidden\r\nHTTP response headers: HTTPHeaderDict({'Audit-Id': '996ed046-f740-41c1-b595-bfa8fd027c5a', 'Cache-Control': 'no-cache, private', 'Content-Type': 'application/json', 'X-Content-Type-Options': 'nosniff', 'X-Kubernetes-Pf-Flowschema-Uid': '1618daa5-11f3-48e2-a78a-c4bd85946f89', 'X-Kubernetes-Pf-Prioritylevel-Uid': 'e69797fa-2560-4952-9d6b-c2c49a120b33', 'Date': 'Tue, 15 Dec 2020 19:41:20 GMT', 'Content-Length': '392'})\r\nHTTP response body: b'{\"kind\":\"Status\",\"apiVersion\":\"v1\",\"metadata\":{},\"status\":\"Failure\",\"message\":\"machinesets.machine.openshift.io is forbidden: User \\\\\"system:serviceaccount:default:onboarding\\\\\" cannot list resource \\\\\"machinesets\\\\\" in API group \\\\\"machine.openshift.io\\\\\" in the namespace \\\\\"openshift-machine-api\\\\\"\",\"reason\":\"Forbidden\",\"details\":{\"group\":\"machine.openshift.io\",\"kind\":\"machinesets\"},\"code\":403}\\n'\r\nOriginal traceback: \r\n  File \"/usr/local/lib/python3.6/site-packages/openshift/dynamic/client.py\", line 42, in inner\r\n    resp = func(self, *args, **kwargs)\r\n\r\n  File \"/usr/local/lib/python3.6/site-packages/openshift/dynamic/client.py\", line 247, in request\r\n    _return_http_data_only=params.get('_return_http_data_only', True)\r\n\r\n  File \"/usr/local/lib/python3.6/site-packages/kubernetes/client/api_client.py\", line 345, in call_api\r\n    _preload_content, _request_timeout)\r\n\r\n  File \"/usr/local/lib/python3.6/site-packages/kubernetes/client/api_client.py\", line 176, in __call_api\r\n    _request_timeout=_request_timeout)\r\n\r\n  File \"/usr/local/lib/python3.6/site-packages/kubernetes/client/api_client.py\", line 366, in request\r\n    headers=headers)\r\n\r\n  File \"/usr/local/lib/python3.6/site-packages/kubernetes/client/rest.py\", line 241, in GET\r\n    query_params=query_params)\r\n\r\n  File \"/usr/local/lib/python3.6/site-packages/kubernetes/client/rest.py\", line 231, in request\r\n    raise ApiException(http_resp=r)\r\n\r\n", "msg": "MODULE FAILURE\nSee stdout/stderr for the exact error", "rc": 1}
fatal: [bastion-ocp4-int-prod-west]: FAILED! => {"changed": false, "module_stderr": "Shared connection to 10.244.84.221 closed.\r\n", "module_stdout": "Traceback (most recent call last):\r\n  File \"/usr/local/lib/python3.6/site-packages/openshift/dynamic/client.py\", line 42, in inner\r\n    resp = func(self, *args, **kwargs)\r\n  File \"/usr/local/lib/python3.6/site-packages/openshift/dynamic/client.py\", line 247, in request\r\n    _return_http_data_only=params.get('_return_http_data_only', True)\r\n  File \"/usr/local/lib/python3.6/site-packages/kubernetes/client/api_client.py\", line 345, in call_api\r\n    _preload_content, _request_timeout)\r\n  File \"/usr/local/lib/python3.6/site-packages/kubernetes/client/api_client.py\", line 176, in __call_api\r\n    _request_timeout=_request_timeout)\r\n  File \"/usr/local/lib/python3.6/site-packages/kubernetes/client/api_client.py\", line 366, in request\r\n    headers=headers)\r\n  File \"/usr/local/lib/python3.6/site-packages/kubernetes/client/rest.py\", line 241, in GET\r\n    query_params=query_params)\r\n  File \"/usr/local/lib/python3.6/site-packages/kubernetes/client/rest.py\", line 231, in request\r\n    raise ApiException(http_resp=r)\r\nkubernetes.client.rest.ApiException: (403)\r\nReason: Forbidden\r\nHTTP response headers: HTTPHeaderDict({'Audit-Id': 'f6a29676-9159-4a6d-ae36-41326ce5f3c6', 'Cache-Control': 'no-cache, private', 'Content-Type': 'application/json', 'X-Content-Type-Options': 'nosniff', 'X-Kubernetes-Pf-Flowschema-Uid': 'e14f3bf3-1025-4aec-aa38-a97dca05d67f', 'X-Kubernetes-Pf-Prioritylevel-Uid': 'ebd42b9e-0157-4eb0-be5b-a7c02c902b4c', 'Date': 'Tue, 15 Dec 2020 19:41:20 GMT', 'Content-Length': '392'})\r\nHTTP response body: b'{\"kind\":\"Status\",\"apiVersion\":\"v1\",\"metadata\":{},\"status\":\"Failure\",\"message\":\"machinesets.machine.openshift.io is forbidden: User \\\\\"system:serviceaccount:default:onboarding\\\\\" cannot list resource \\\\\"machinesets\\\\\" in API group \\\\\"machine.openshift.io\\\\\" in the namespace \\\\\"openshift-machine-api\\\\\"\",\"reason\":\"Forbidden\",\"details\":{\"group\":\"machine.openshift.io\",\"kind\":\"machinesets\"},\"code\":403}\\n'\r\n\r\n\r\nDuring handling of the above exception, another exception occurred:\r\n\r\nTraceback (most recent call last):\r\n  File \"/home/ec2-user/.ansible/tmp/ansible-tmp-1608061278.64-50554508032202/AnsiballZ_k8s_facts.py\", line 114, in <module>\r\n    _ansiballz_main()\r\n  File \"/home/ec2-user/.ansible/tmp/ansible-tmp-1608061278.64-50554508032202/AnsiballZ_k8s_facts.py\", line 106, in _ansiballz_main\r\n    invoke_module(zipped_mod, temp_path, ANSIBALLZ_PARAMS)\r\n  File \"/home/ec2-user/.ansible/tmp/ansible-tmp-1608061278.64-50554508032202/AnsiballZ_k8s_facts.py\", line 49, in invoke_module\r\n    imp.load_module('__main__', mod, module, MOD_DESC)\r\n  File \"/usr/lib64/python3.6/imp.py\", line 235, in load_module\r\n    return load_source(name, filename, file)\r\n  File \"/usr/lib64/python3.6/imp.py\", line 170, in load_source\r\n    module = _exec(spec, sys.modules[name])\r\n  File \"<frozen importlib._bootstrap>\", line 618, in _exec\r\n  File \"<frozen importlib._bootstrap_external>\", line 678, in exec_module\r\n  File \"<frozen importlib._bootstrap>\", line 219, in _call_with_frames_removed\r\n  File \"/tmp/ansible_k8s_facts_payload_tkgh23r0/__main__.py\", line 176, in <module>\r\n  File \"/tmp/ansible_k8s_facts_payload_tkgh23r0/__main__.py\", line 172, in main\r\n  File \"/tmp/ansible_k8s_facts_payload_tkgh23r0/__main__.py\", line 153, in execute_module\r\n  File \"/tmp/ansible_k8s_facts_payload_tkgh23r0/ansible_k8s_facts_payload.zip/ansible/module_utils/k8s/common.py\", line 206, in kubernetes_facts\r\n  File \"/usr/local/lib/python3.6/site-packages/openshift/dynamic/client.py\", line 94, in get\r\n    return self.request('get', path, **kwargs)\r\n  File \"/usr/local/lib/python3.6/site-packages/openshift/dynamic/client.py\", line 44, in inner\r\n    raise api_exception(e)\r\nopenshift.dynamic.exceptions.ForbiddenError: 403\r\nReason: Forbidden\r\nHTTP response headers: HTTPHeaderDict({'Audit-Id': 'f6a29676-9159-4a6d-ae36-41326ce5f3c6', 'Cache-Control': 'no-cache, private', 'Content-Type': 'application/json', 'X-Content-Type-Options': 'nosniff', 'X-Kubernetes-Pf-Flowschema-Uid': 'e14f3bf3-1025-4aec-aa38-a97dca05d67f', 'X-Kubernetes-Pf-Prioritylevel-Uid': 'ebd42b9e-0157-4eb0-be5b-a7c02c902b4c', 'Date': 'Tue, 15 Dec 2020 19:41:20 GMT', 'Content-Length': '392'})\r\nHTTP response body: b'{\"kind\":\"Status\",\"apiVersion\":\"v1\",\"metadata\":{},\"status\":\"Failure\",\"message\":\"machinesets.machine.openshift.io is forbidden: User \\\\\"system:serviceaccount:default:onboarding\\\\\" cannot list resource \\\\\"machinesets\\\\\" in API group \\\\\"machine.openshift.io\\\\\" in the namespace \\\\\"openshift-machine-api\\\\\"\",\"reason\":\"Forbidden\",\"details\":{\"group\":\"machine.openshift.io\",\"kind\":\"machinesets\"},\"code\":403}\\n'\r\nOriginal traceback: \r\n  File \"/usr/local/lib/python3.6/site-packages/openshift/dynamic/client.py\", line 42, in inner\r\n    resp = func(self, *args, **kwargs)\r\n\r\n  File \"/usr/local/lib/python3.6/site-packages/openshift/dynamic/client.py\", line 247, in request\r\n    _return_http_data_only=params.get('_return_http_data_only', True)\r\n\r\n  File \"/usr/local/lib/python3.6/site-packages/kubernetes/client/api_client.py\", line 345, in call_api\r\n    _preload_content, _request_timeout)\r\n\r\n  File \"/usr/local/lib/python3.6/site-packages/kubernetes/client/api_client.py\", line 176, in __call_api\r\n    _request_timeout=_request_timeout)\r\n\r\n  File \"/usr/local/lib/python3.6/site-packages/kubernetes/client/api_client.py\", line 366, in request\r\n    headers=headers)\r\n\r\n  File \"/usr/local/lib/python3.6/site-packages/kubernetes/client/rest.py\", line 241, in GET\r\n    query_params=query_params)\r\n\r\n  File \"/usr/local/lib/python3.6/site-packages/kubernetes/client/rest.py\", line 231, in request\r\n    raise ApiException(http_resp=r)\r\n\r\n", "msg": "MODULE FAILURE\nSee stdout/stderr for the exact error", "rc": 1}
fatal: [bastion-ocp4-int-dev-east]: FAILED! => {"changed": false, "module_stderr": "Shared connection to 10.211.160.245 closed.\r\n", "module_stdout": "Traceback (most recent call last):\r\n  File \"/usr/local/lib/python3.6/site-packages/openshift/dynamic/client.py\", line 42, in inner\r\n    resp = func(self, *args, **kwargs)\r\n  File \"/usr/local/lib/python3.6/site-packages/openshift/dynamic/client.py\", line 247, in request\r\n    _return_http_data_only=params.get('_return_http_data_only', True)\r\n  File \"/usr/local/lib/python3.6/site-packages/kubernetes/client/api_client.py\", line 345, in call_api\r\n    _preload_content, _request_timeout)\r\n  File \"/usr/local/lib/python3.6/site-packages/kubernetes/client/api_client.py\", line 176, in __call_api\r\n    _request_timeout=_request_timeout)\r\n  File \"/usr/local/lib/python3.6/site-packages/kubernetes/client/api_client.py\", line 366, in request\r\n    headers=headers)\r\n  File \"/usr/local/lib/python3.6/site-packages/kubernetes/client/rest.py\", line 241, in GET\r\n    query_params=query_params)\r\n  File \"/usr/local/lib/python3.6/site-packages/kubernetes/client/rest.py\", line 231, in request\r\n    raise ApiException(http_resp=r)\r\nkubernetes.client.rest.ApiException: (403)\r\nReason: Forbidden\r\nHTTP response headers: HTTPHeaderDict({'Audit-Id': '50ea9a69-7b8c-4b7b-af17-4b95f292c75d', 'Cache-Control': 'no-cache, private', 'Content-Type': 'application/json', 'X-Content-Type-Options': 'nosniff', 'X-Kubernetes-Pf-Flowschema-Uid': '07e8cf50-ed04-45b3-b934-7e78feb12940', 'X-Kubernetes-Pf-Prioritylevel-Uid': '1baeb0c0-775a-4ca0-a46e-b26d79861c62', 'Date': 'Tue, 15 Dec 2020 19:41:21 GMT', 'Content-Length': '392'})\r\nHTTP response body: b'{\"kind\":\"Status\",\"apiVersion\":\"v1\",\"metadata\":{},\"status\":\"Failure\",\"message\":\"machinesets.machine.openshift.io is forbidden: User \\\\\"system:serviceaccount:default:onboarding\\\\\" cannot list resource \\\\\"machinesets\\\\\" in API group \\\\\"machine.openshift.io\\\\\" in the namespace \\\\\"openshift-machine-api\\\\\"\",\"reason\":\"Forbidden\",\"details\":{\"group\":\"machine.openshift.io\",\"kind\":\"machinesets\"},\"code\":403}\\n'\r\n\r\n\r\nDuring handling of the above exception, another exception occurred:\r\n\r\nTraceback (most recent call last):\r\n  File \"/home/ec2-user/.ansible/tmp/ansible-tmp-1608061280.2-78210659601366/AnsiballZ_k8s_facts.py\", line 114, in <module>\r\n    _ansiballz_main()\r\n  File \"/home/ec2-user/.ansible/tmp/ansible-tmp-1608061280.2-78210659601366/AnsiballZ_k8s_facts.py\", line 106, in _ansiballz_main\r\n    invoke_module(zipped_mod, temp_path, ANSIBALLZ_PARAMS)\r\n  File \"/home/ec2-user/.ansible/tmp/ansible-tmp-1608061280.2-78210659601366/AnsiballZ_k8s_facts.py\", line 49, in invoke_module\r\n    imp.load_module('__main__', mod, module, MOD_DESC)\r\n  File \"/usr/lib64/python3.6/imp.py\", line 235, in load_module\r\n    return load_source(name, filename, file)\r\n  File \"/usr/lib64/python3.6/imp.py\", line 170, in load_source\r\n    module = _exec(spec, sys.modules[name])\r\n  File \"<frozen importlib._bootstrap>\", line 618, in _exec\r\n  File \"<frozen importlib._bootstrap_external>\", line 678, in exec_module\r\n  File \"<frozen importlib._bootstrap>\", line 219, in _call_with_frames_removed\r\n  File \"/tmp/ansible_k8s_facts_payload_ud897cf_/__main__.py\", line 176, in <module>\r\n  File \"/tmp/ansible_k8s_facts_payload_ud897cf_/__main__.py\", line 172, in main\r\n  File \"/tmp/ansible_k8s_facts_payload_ud897cf_/__main__.py\", line 153, in execute_module\r\n  File \"/tmp/ansible_k8s_facts_payload_ud897cf_/ansible_k8s_facts_payload.zip/ansible/module_utils/k8s/common.py\", line 206, in kubernetes_facts\r\n  File \"/usr/local/lib/python3.6/site-packages/openshift/dynamic/client.py\", line 94, in get\r\n    return self.request('get', path, **kwargs)\r\n  File \"/usr/local/lib/python3.6/site-packages/openshift/dynamic/client.py\", line 44, in inner\r\n    raise api_exception(e)\r\nopenshift.dynamic.exceptions.ForbiddenError: 403\r\nReason: Forbidden\r\nHTTP response headers: HTTPHeaderDict({'Audit-Id': '50ea9a69-7b8c-4b7b-af17-4b95f292c75d', 'Cache-Control': 'no-cache, private', 'Content-Type': 'application/json', 'X-Content-Type-Options': 'nosniff', 'X-Kubernetes-Pf-Flowschema-Uid': '07e8cf50-ed04-45b3-b934-7e78feb12940', 'X-Kubernetes-Pf-Prioritylevel-Uid': '1baeb0c0-775a-4ca0-a46e-b26d79861c62', 'Date': 'Tue, 15 Dec 2020 19:41:21 GMT', 'Content-Length': '392'})\r\nHTTP response body: b'{\"kind\":\"Status\",\"apiVersion\":\"v1\",\"metadata\":{},\"status\":\"Failure\",\"message\":\"machinesets.machine.openshift.io is forbidden: User \\\\\"system:serviceaccount:default:onboarding\\\\\" cannot list resource \\\\\"machinesets\\\\\" in API group \\\\\"machine.openshift.io\\\\\" in the namespace \\\\\"openshift-machine-api\\\\\"\",\"reason\":\"Forbidden\",\"details\":{\"group\":\"machine.openshift.io\",\"kind\":\"machinesets\"},\"code\":403}\\n'\r\nOriginal traceback: \r\n  File \"/usr/local/lib/python3.6/site-packages/openshift/dynamic/client.py\", line 42, in inner\r\n    resp = func(self, *args, **kwargs)\r\n\r\n  File \"/usr/local/lib/python3.6/site-packages/openshift/dynamic/client.py\", line 247, in request\r\n    _return_http_data_only=params.get('_return_http_data_only', True)\r\n\r\n  File \"/usr/local/lib/python3.6/site-packages/kubernetes/client/api_client.py\", line 345, in call_api\r\n    _preload_content, _request_timeout)\r\n\r\n  File \"/usr/local/lib/python3.6/site-packages/kubernetes/client/api_client.py\", line 176, in __call_api\r\n    _request_timeout=_request_timeout)\r\n\r\n  File \"/usr/local/lib/python3.6/site-packages/kubernetes/client/api_client.py\", line 366, in request\r\n    headers=headers)\r\n\r\n  File \"/usr/local/lib/python3.6/site-packages/kubernetes/client/rest.py\", line 241, in GET\r\n    query_params=query_params)\r\n\r\n  File \"/usr/local/lib/python3.6/site-packages/kubernetes/client/rest.py\", line 231, in request\r\n    raise ApiException(http_resp=r)\r\n\r\n", "msg": "MODULE FAILURE\nSee stdout/stderr for the exact error", "rc": 1}
